Workbook

Sheet March 2026
C40: Period Average | E40: Spot Rate/Date | I40: SalesForce Update (use the last day of the previous month)
C41: AED | D41: 3.67251 | E41: AED | F41: 3.67243 | H41: AUD | I41: =VLOOKUP(H41,$E$41:$F$59,2,FALSE) -> 1.45513
C42: AUD | D42: 1.42602 | E42: AUD | F42: 1.45513 | H42: CAD | I42: =VLOOKUP(H42,$E$41:$F$59,2,FALSE) -> 1.39306
C43: CAD | D43: 1.37125 | E43: CAD | F43: 1.39306 | H43: CHF | I43: =VLOOKUP(H43,$E$41:$F$59,2,FALSE) -> 0.799721
C44: CHF | D44: 0.786411 | E44: CHF | F44: 0.799721 | H44: DKK | I44: =VLOOKUP(H44,$E$41:$F$59,2,FALSE) -> 6.49343
C45: DKK | D45: 6.46232 | E45: DKK | F45: 6.49343 | H45: EUR | I45: =VLOOKUP(H45,$E$41:$F$59,2,FALSE) -> 0.869163
C46: EUR | D46: 0.864934 | E46: EUR | F46: 0.869163 | H46: GBP | I46: =VLOOKUP(H46,$E$41:$F$59,2,FALSE) -> 0.75655
C47: GBP | D47: 0.749572 | E47: GBP | F47: 0.75655 | H47: HKD | I47: =VLOOKUP(H47,$E$41:$F$59,2,FALSE) -> 7.83871
C48: HUF | D48: 336.348 | E48: HUF | F48: 334.968 | H48: INR | I48: =VLOOKUP(H48,$E$41:$F$59,2,FALSE) -> 93.8539
C49: JPY | D49: 158.721 | E49: JPY | F49: 159.304 | H49: JPY | I49: =VLOOKUP(H49,$E$41:$F$59,2,FALSE) -> 159.304
C50: NOK | D50: 9.64979 | E50: NOK | F50: 9.73517 | H50: KRW | I50: =VLOOKUP(H50,$E$41:$F$59,2,FALSE) -> 1521.2
C51: NZD | D51: 1.71056 | E51: NZD | F51: 1.74667 | H51: MYR | I51: =VLOOKUP(H51,$E$41:$F$59,2,FALSE) -> 4.0412
C52: RUB | D52: 80.4794 | E52: RUB | F52: 81.3122 | H52: NOK | I52: =VLOOKUP(H52,$E$41:$F$59,2,FALSE) -> 9.73517
... C55: ZAR | D55: 16.742 | E55: ZAR | F55: 17.05 | H55: SGD | I55: =VLOOKUP(H55,$E$41:$F$59,2,FALSE) -> 1.28884
E56: INR | F56: 93.8539
E57: KRW | F57: 1521.2
E58: MYR | F58: 4.0412
E59: HKD | F59: 7.83871

Sheet Summary
F1: Valid From | G1: Exchange Rate
A2: 1002 | B2: AED | C2: USD | D2: USD/AED | E2: 0.042361111 | F2: 46112 | G2: ='March 2026'!D41 -> 3.67251 | H2: =ROUND(G2,4) -> 3.6725 | I2: Period Average
A3: 1002 | B3: AUD | C3: USD | D3: USD/AUD | E3: 0.042361111 | F3: =F2 -> 46112 | G3: ='March 2026'!D42 -> 1.42602 | H3: =ROUND(G3,4) -> 1.426
A4: 1002 | B4: CAD | C4: USD | D4: USD/CAD | E4: 0.042361111 | F4: =F3 -> 46112 | G4: ='March 2026'!D43 -> 1.37125 | H4: =ROUND(G4,4) -> 1.3713
A5: 1002 | B5: CHF | C5: USD | D5: USD/CHF | E5: 0.042361111 | F5: =F4 -> 46112 | G5: ='March 2026'!D44 -> 0.786411 | H5: =ROUND(G5,4) -> 0.7864
A6: 1002 | B6: DKK | C6: USD | D6: USD/DKK | E6: 0.042361111 | F6: =F5 -> 46112 | G6: ='March 2026'!D45 -> 6.46232 | H6: =ROUND(G6,4) -> 6.4623
A7: 1002 | B7: EUR | C7: USD | D7: USD/EUR | E7: 0.042361111 | F7: =F6 -> 46112 | G7: ='March 2026'!D46 -> 0.864934 | H7: =ROUND(G7,4) -> 0.8649
A8: 1002 | B8: GBP | C8: USD | D8: USD/GBP | E8: 0.042361111 | F8: =F7 -> 46112 | G8: ='March 2026'!D47 -> 0.749572 | H8: =ROUND(G8,4) -> 0.7496
A9: 1002 | B9: HUF | C9: USD | D9: USD/HUF | E9: 0.042361111 | F9: =F8 -> 46112 | G9: ='March 2026'!D48 -> 336.348 | H9: =ROUND(G9,4) -> 336.348
A10: 1002 | B10: JPY | C10: USD | D10: USD/JPY | E10: 0.042361111 | F10: =F9 -> 46112 | G10: ='March 2026'!D49 -> 158.721 | H10: =ROUND(G10,4) -> 158.721
A11: 1002 | B11: NOK | C11: USD | D11: USD/NOK | E11: 0.042361111 | F11: =F10 -> 46112 | G11: ='March 2026'!D50 -> 9.64979 | H11: =ROUND(G11,4) -> 9.6498
A12: 1002 | B12: NZD | C12: USD | D12: USD/NZD | E12: 0.042361111 | F12: =F11 -> 46112 | G12: ='March 2026'!D51 -> 1.71056 | H12: =ROUND(G12,4) -> 1.7106
A13: 1002 | B13: RUB | C13: USD | D13: USD/RUB | E13: 0.042361111 | F13: =F12 -> 46112 | G13: ='March 2026'!D52 -> 80.4794 | H13: =ROUND(G13,4) -> 80.4794
A14: 1002 | B14: SEK | C14: USD | D14: USD/SEK | E14: 0.042361111 | F14: =F13 -> 46112 | G14: ='March 2026'!D53 -> 9.31309 | H14: =ROUND(G14,4) -> 9.3131
... A16: 1002 | B16: ZAR | C16: USD | D16: USD/ZAR | E16: 0.042361111 | F16: =F15 -> 46112 | G16: ='March 2026'!D55 -> 16.742 | H16: =ROUND(G16,4) -> 16.742
A17: M | B17: AED | C17: USD | D17: USD/AED | E17: 0.042361111 | F17: =F16 -> 46112 | G17: ='March 2026'!F41 -> 3.67243 | H17: =ROUND(G17,4) -> 3.6724 | I17: Spot
A18: M | B18: AUD | C18: USD | D18: USD/AUD | E18: 0.042361111 | F18: =F17 -> 46112 | G18: ='March 2026'!F42 -> 1.45513 | H18: =ROUND(G18,4) -> 1.4551
A19: M | B19: CAD | C19: USD | D19: USD/CAD | E19: 0.042361111 | F19: =F18 -> 46112 | G19: ='March 2026'!F43 -> 1.39306 | H19: =ROUND(G19,4) -> 1.3931
A20: M | B20: CHF | C20: USD | D20: USD/CHF | E20: 0.042361111 | F20: =F19 -> 46112 | G20: ='March 2026'!F44 -> 0.799721 | H20: =ROUND(G20,4) -> 0.7997
A21: M | B21: DKK | C21: USD | D21: USD/DKK | E21: 0.042361111 | F21: =F20 -> 46112 | G21: ='March 2026'!F45 -> 6.49343 | H21: =ROUND(G21,4) -> 6.4934
A22: M | B22: EUR | C22: USD | D22: USD/EUR | E22: 0.042361111 | F22: =F21 -> 46112 | G22: ='March 2026'!F46 -> 0.869163 | H22: =ROUND(G22,4) -> 0.8692
A23: M | B23: GBP | C23: USD | D23: USD/GBP | E23: 0.042361111 | F23: =F22 -> 46112 | G23: ='March 2026'!F47 -> 0.75655 | H23: =ROUND(G23,4) -> 0.7566
A24: M | B24: HUF | C24: USD | D24: USD/HUF | E24: 0.042361111 | F24: =F23 -> 46112 | G24: ='March 2026'!F48 -> 334.968 | H24: =ROUND(G24,4) -> 334.968
A25: M | B25: JPY | C25: USD | D25: USD/JPY | E25: 0.042361111 | F25: =F24 -> 46112 | G25: ='March 2026'!F49 -> 159.304 | H25: =ROUND(G25,4) -> 159.304
A26: M | B26: NOK | C26: USD | D26: USD/NOK | E26: 0.042361111 | F26: =F25 -> 46112 | G26: ='March 2026'!F50 -> 9.73517 | H26: =ROUND(G26,4) -> 9.7352
A27: M | B27: NZD | C27: USD | D27: USD/NZD | E27: 0.042361111 | F27: =F26 -> 46112 | G27: ='March 2026'!F51 -> 1.74667 | H27: =ROUND(G27,4) -> 1.7467
A28: M | B28: RUB | C28: USD | D28: USD/RUB | E28: 0.042361111 | F28: =F27 -> 46112 | G28: ='March 2026'!F52 -> 81.3122 | H28: =ROUND(G28,4) -> 81.3122
A29: M | B29: SEK | C29: USD | D29: USD/SEK | E29: 0.042361111 | F29: =F28 -> 46112 | G29: ='March 2026'!F53 -> 9.51792 | H29: =ROUND(G29,4) -> 9.5179
... A31: M | B31: ZAR | C31: USD | D31: USD/ZAR | E31: 0.042361111 | F31: =F30 -> 46112 | G31: ='March 2026'!F55 -> 17.05 | H31: =ROUND(G31,4) -> 17.05
B33: AED
B34: AUD
B35: CAD
B36: CHF
B37: DKK
B38: EUR
B39: GBP
B40: HKD
B41: HUF
B42: INR
B43: JPY
...

Sheet Sherry
A1: Month_Yr | B1: AUD | C1: CAD | D1: CHF | E1: EUR | F1: GBP | G1: JPY | H1: NZD | I1: SGD | J1: DKK | K1: SEK | L1: NOK
A2: =Summary!F3 -> 46112 | B2: =1/Summary!$G18 -> 0.68722382 | C2: =1/Summary!$G19 -> 0.71784417 | D2: =1/Summary!$G20 -> 1.2504361 | E2: =1/Summary!$G22 -> 1.1505322 | F2: =1/Summary!$G23 -> 1.3217897 | G2: =1/Summary!$G25 -> 0.0062773063 | H2: =1/Summary!$G27 -> 0.57251799 | I2: =1/Summary!$G30 -> 0.7758915 | J2: =1/Summary!$G21 -> 0.15400181 | K2: =1/Summary!$G29 -> 0.10506497 | L2: =1/Summary!$G26 -> 0.10272034
A4: Note: This exchage rate is converting 1 foreign dollar to USD.
A5: To calculate USD, take Foreign dollar X the exchange rate
A6: Example: | B6: Foreign Amt | C6: Currency | D6: USD
B7: 1000 | C7: AUD | D7: =B7*B2 -> 687.22382
B8: 1000 | C8: CAD | D8: =B8*C2 -> 717.84417
B9: 1000000 | C9: JPY | D9: =B9*G2 -> 6277.3063
